Workbook

Sheet fonds
A1: md5 | B1: fondsid | C1: atom:id | D1: unittile | E1: from | F1: to | G1: papals_text | H1: papals_cv
A2: AT-ATF/9422807890ecf0d2df38a5f81699b08f | B2: AT-ATF/TirolOFM | C2: tag:www.monasterium.net,2011:/fond/AT-ATF/TirolOFM | D2: Tiroler Franziskanerprovinz (1229-1970) | E2: =VLOOKUP($B2, temporalBoundaries!$A:$G, 6, 0) -> 12290220 | F2: =VLOOKUP($B2, temporalBoundaries!$A:$G, 7, 0) -> 19700409
A3: AT-AWMK/730db1bb5405e6e10c3fddc5e85baa21 | B3: AT-AWMK/WienOFMConv | C3: tag:www.monasterium.net,2011:/fond/AT-AWMK/WienOFMConv | D3: Urkunden Wien (1243-1765) | E3: =VLOOKUP($B3,temporalBoundaries!$A:$G,6,0) -> 12430629 | F3: =VLOOKUP($B3,temporalBoundaries!$A:$G,7,0) -> 17650422 | G3: 63
A4: AT-AWMK/838ec3d67f2b61a38108db5991a1a199 | B4: AT-AWMK/NeunkirchenOFMConv | C4: tag:www.monasterium.net,2011:/fond/AT-AWMK/NeunkirchenOFMConv | D4: Urkunden Neukirchen (1368-1830) | E4: =VLOOKUP($B4,temporalBoundaries!$A:$G,6,0) -> 13681213 | F4: =VLOOKUP($B4,temporalBoundaries!$A:$G,7,0) -> 18309999
A5: AT-AWMK/efcd58a04c971d71ae20524c11cefe16 | B5: AT-AWMK/AsparnOFMConv | C5: tag:www.monasterium.net,2011:/fond/AT-AWMK/AsparnOFMConv | D5: Urkunden Asparn (1471-1767) | E5: =VLOOKUP($B5,temporalBoundaries!$A:$G,6,0) -> 14711127 | F5: =VLOOKUP($B5,temporalBoundaries!$A:$G,7,0) -> 17670520 | G5: 25
A6: AT-HHStA/005e12399a92512465952936e23c20f5 | B6: AT-HHStA/WienStLaurCanReg | C6: tag:www.monasterium.net,2011:/fond/AT-HHStA/WienStLaurCanReg | D6: Wien, St. Laurenz - Augustiner-Chorfrauen | E6: =VLOOKUP($B6,temporalBoundaries!$A:$G,6,0) -> 13161021 | F6: =VLOOKUP($B6,temporalBoundaries!$A:$G,7,0) -> 17820622
A7: AT-HHStA/04fd7de1af923d15458329ed4d5983e6 | B7: AT-HHStA/WiltenOPraem | C7: tag:www.monasterium.net,2011:/fond/AT-HHStA/WiltenOPraem | D7: Wilten, Prämonstratenser (1180-1488) | E7: =VLOOKUP($B7,temporalBoundaries!$A:$G,6,0) -> 11881214 | F7: =VLOOKUP($B7,temporalBoundaries!$A:$G,7,0) -> 14880117
A8: AT-HHStA/0578bae529517424bc4dacc480d747cb | B8: AT-HHStA/SeckauCanReg | C8: tag:www.monasterium.net,2011:/fond/AT-HHStA/SeckauCanReg | D8: Seckau, Augustiner-Chorherren (1170-1489) | E8: =VLOOKUP($B8,temporalBoundaries!$A:$G,6,0) -> 11711231 | F8: =VLOOKUP($B8,temporalBoundaries!$A:$G,7,0) -> 14890721
A9: AT-HHStA/07e705c7f8fcc94f98cdf7192aea86d5 | B9: AT-HHStA/EbersbergOSB | C9: tag:www.monasterium.net,2011:/fond/AT-HHStA/EbersbergOSB | D9: Ebersberg, Benediktiner (1247-1481) | E9: =VLOOKUP($B9,temporalBoundaries!$A:$G,6,0) -> 12479999 | F9: =VLOOKUP($B9,temporalBoundaries!$A:$G,7,0) -> 14181011
A10: AT-HHStA/0bc40b0184ca385dcc9f0a320889a6d2 | B10: AT-HHStA/AltenburgOSB | C10: tag:www.monasterium.net,2011:/fond/AT-HHStA/AltenburgOSB | D10: Altenburg, Benediktiner (1144-1943) | E10: =VLOOKUP($B10, temporalBoundaries!$A:$G, 6, 0) -> 12820905 | F10: =VLOOKUP($B10, temporalBoundaries!$A:$G, 7, 0) -> 13400424
A11: AT-HHStA/0ddc6372d580849fd2c98409318f2f15 | B11: AT-HHStA/StLambrechtOSB | C11: tag:www.monasterium.net,2011:/fond/AT-HHStA/StLambrechtOSB | D11: St. Lambrecht, Benediktiner (1205-1580) | E11: =VLOOKUP($B11,temporalBoundaries!$A:$G,6,0) -> 12051110 | F11: =VLOOKUP($B11,temporalBoundaries!$A:$G,7,0) -> 15800128 | G11: 1
A12: AT-HHStA/1126e531b1f42d06545c5f2718b59ad3 | B12: AT-HHStA/ArnsburgOCist | C12: tag:www.monasterium.net,2011:/fond/AT-HHStA/ArnsburgOCist | D12: Arnsburg, Zisterzienser | E12: =VLOOKUP($B12,temporalBoundaries!$A:$G,6,0) -> 14560122 | F12: =VLOOKUP($B12,temporalBoundaries!$A:$G,7,0) -> 14560122
A13: AT-HHStA/12feb23869c2117bd304b71090b016cc | B13: AT-HHStA/WolfsbergOFMConv | C13: tag:www.monasterium.net,2011:/fond/AT-HHStA/WolfsbergOFMConv | D13: Wolfsberg, Minoriten (1456-1624) | E13: =VLOOKUP($B13,temporalBoundaries!$A:$G,6,0) -> 14560305 | F13: =VLOOKUP($B13,temporalBoundaries!$A:$G,7,0) -> 16240121
A14: AT-HHStA/18c6a514e84f0fb9983dccd0dda0f4c1 | B14: AT-HHStA/MekinjeOSCI | C14: tag:www.monasterium.net,2011:/fond/AT-HHStA/MekinjeOSCI | D14: Mekinje (dt. Minkendorf), Klarissen (1287-1545) | E14: =VLOOKUP($B14,temporalBoundaries!$A:$G,6,0) -> 13501123 | F14: =VLOOKUP($B14,temporalBoundaries!$A:$G,7,0) -> 15450424
A15: AT-HHStA/1e211c956d2298bc9d02e177fcfdbede | B15: AT-HHStA/ThalbachOFM | C15: tag:www.monasterium.net,2011:/fond/AT-HHStA/ThalbachOFM | D15: Thalbach, Franziskanerinnen (1479-1780) | E15: =VLOOKUP($B15,temporalBoundaries!$A:$G,6,0) -> 14790124 | F15: =VLOOKUP($B15,temporalBoundaries!$A:$G,7,0) -> 17800115
A16: AT-HHStA/1e9469b249a8c7f0df2f36273e4b2f49 | B16: AT-HHStA/StBernhardOCist | C16: tag:www.monasterium.net,2011:/fond/AT-HHStA/StBernhardOCist | D16: St. Bernhard, Zisterzienserinnen (1263-1571) | E16: =VLOOKUP($B16,temporalBoundaries!$A:$G,6,0) -> 12630507 | F16: =VLOOKUP($B16,temporalBoundaries!$A:$G,7,0) -> 14880417
A17: AT-HHStA/209b4c152123964a8f26bef7c1995664 | B17: AT-HHStA/WienStNiklaskloster | C17: tag:www.monasterium.net,2011:/fond/AT-HHStA/WienStNiklaskloster | D17: Wien, St. Niklaskloster | E17: =VLOOKUP($B17,temporalBoundaries!$A:$G,6,0) -> 14340929 | F17: =VLOOKUP($B17,temporalBoundaries!$A:$G,7,0) -> 14340929
A18: AT-HHStA/2126a8f795a598014121268b46b2dc9d | B18: AT-HHStA/YbbsOCist | C18: tag:www.monasterium.net,2011:/fond/AT-HHStA/YbbsOCist | D18: Ybbs, Zisterzienserinnen (1234-1656) | E18: =VLOOKUP($B18,temporalBoundaries!$A:$G,6,0) -> 12341207 | F18: =VLOOKUP($B18,temporalBoundaries!$A:$G,7,0) -> 14171122
A19: AT-HHStA/21ed90366f1510116cdb8aa52ff05a48 | B19: AT-HHStA/GrosswardeinOPraem | C19: tag:www.monasterium.net,2011:/fond/AT-HHStA/GrosswardeinOPraem | D19: Großwardein, Prämonstratenser | E19: =VLOOKUP($B19,temporalBoundaries!$A:$G,6,0) -> 13330616 | F19: =VLOOKUP($B19,temporalBoundaries!$A:$G,7,0) -> 13330616
A20: AT-HHStA/284172994a2e3cb149aa3fe0553ab152 | B20: AT-HHStA/NRannaOSPPE | C20: tag:www.monasterium.net,2011:/fond/AT-HHStA/NRannaOSPPE | D20: Niederranna, Pauliner (1363-1685) | E20: =VLOOKUP($B20,temporalBoundaries!$A:$G,6,0) -> 14360801 | F20: =VLOOKUP($B20,temporalBoundaries!$A:$G,7,0) -> 16851218
A21: AT-HHStA/28b069bed180c38f14fdab0075dfa8c1 | B21: AT-HHStA/GloggnitzOSB | C21: tag:www.monasterium.net,2011:/fond/AT-HHStA/GloggnitzOSB | D21: Gloggnitz, Benediktiner (1476) | E21: =VLOOKUP($B21,temporalBoundaries!$A:$G,6,0) -> 14760406 | F21: =VLOOKUP($B21,temporalBoundaries!$A:$G,7,0) -> 14760406
A22: AT-HHStA/28dcffec83df9ea99c67dc00973cd753 | B22: AT-HHStA/ImbachOP | C22: tag:www.monasterium.net,2011:/fond/AT-HHStA/ImbachOP | D22: Imbach, Dominikanerinnen (1267-1764) | E22: =VLOOKUP($B22,temporalBoundaries!$A:$G,6,0) -> 12731219 | F22: =VLOOKUP($B22,temporalBoundaries!$A:$G,7,0) -> 15680401 | G22: 6
A23: AT-HHStA/2a1483a734de132d55b43aa5c6db38e7 | B23: AT-HHStA/WNStPeterSpOP | C23: tag:www.monasterium.net,2011:/fond/AT-HHStA/WNStPeterSpOP | D23: Wr. Neustadt, St. Peter in der Sperr, Dominikanerinnen (1301-1572) | E23: =VLOOKUP($B23,temporalBoundaries!$A:$G,6,0) -> 13490312 | F23: =VLOOKUP($B23,temporalBoundaries!$A:$G,7,0) -> 15720815
A24: AT-HHStA/2a364391d1a49d7ff9cf6c85f9bace18 | B24: AT-HHStA/StrebnitzOSB | C24: tag:www.monasterium.net,2011:/fond/AT-HHStA/StrebnitzOSB | D24: Strebnitz, Benediktiner | E24: =VLOOKUP($B24,temporalBoundaries!$A:$G,6,0) -> 14680325 | F24: =VLOOKUP($B24,temporalBoundaries!$A:$G,7,0) -> 14680325
A25: AT-HHStA/2bd681e85fd0627a24614ac5afc555ea | B25: AT-HHStA/RadljeOP | C25: tag:www.monasterium.net,2011:/fond/AT-HHStA/RadljeOP | D25: Radlje (dt. Mahrenberg), Dominikanerinnen (1268-1461) | E25: =VLOOKUP($B25,temporalBoundaries!$A:$G,6,0) -> 12681231 | F25: =VLOOKUP($B25,temporalBoundaries!$A:$G,7,0) -> 14610527
A26: AT-HHStA/2e6549a27d028c145f774d2ce33e663b | B26: AT-HHStA/SchnalsOCart | C26: tag:www.monasterium.net,2011:/fond/AT-HHStA/SchnalsOCart | D26: Schnals, Kartäuser | E26: =VLOOKUP($B26,temporalBoundaries!$A:$G,6,0) -> 14340531 | F26: =VLOOKUP($B26,temporalBoundaries!$A:$G,7,0) -> 14340531
A27: AT-HHStA/2f35e9f8cc6edcdfd441fbc73fe0bab4 | B27: AT-HHStA/KleinmariazellOSB | C27: tag:www.monasterium.net,2011:/fond/AT-HHStA/KleinmariazellOSB | D27: Kleinmariazell, Benediktiner | E27: =VLOOKUP($B27,temporalBoundaries!$A:$G,6,0) -> 14670714 | F27: =VLOOKUP($B27,temporalBoundaries!$A:$G,7,0) -> 14670714
A28: AT-HHStA/2f80f5d2a20ed0b3c237e74d53fa2311 | B28: AT-HHStA/PrahaMgd | C28: tag:www.monasterium.net,2011:/fond/AT-HHStA/PrahaMgd | D28: Praha, Magdalenitinen (1398) | E28: =VLOOKUP($B28,temporalBoundaries!$A:$G,6,0) -> 13980525 | F28: =VLOOKUP($B28,temporalBoundaries!$A:$G,7,0) -> 13980525
A29: AT-HHStA/394845fa8ba5789a14f83b35d3819191 | B29: AT-HHStA/GamingOCart | C29: tag:www.monasterium.net,2011:/fond/AT-HHStA/GamingOCart | D29: Gaming, Kartäuser (1311-1753) | E29: =VLOOKUP($B29,temporalBoundaries!$A:$G,6,0) -> 13560601 | F29: =VLOOKUP($B29,temporalBoundaries!$A:$G,7,0) -> 13560601
A30: AT-HHStA/3c4547862e4046b95ba7b8ff63c61df3 | B30: AT-HHStA/KlingenthalOP | C30: tag:www.monasterium.net,2011:/fond/AT-HHStA/KlingenthalOP | D30: Klingenthal, Dominikanerinnen (1482-1483) | E30: =VLOOKUP($B30,temporalBoundaries!$A:$G,6,0) -> 14820312 | F30: =VLOOKUP($B30,temporalBoundaries!$A:$G,7,0) -> 14830311
A31: AT-HHStA/42fb5072123bcbad66bbdbb1eb32c3c5 | B31: AT-HHStA/ErlaOSB | C31: tag:www.monasterium.net,2011:/fond/AT-HHStA/ErlaOSB | D31: Erla, Benediktinerinnen (1050-1742) | E31: =VLOOKUP($B31,temporalBoundaries!$A:$G,6,0) -> 12391126 | F31: =VLOOKUP($B31,temporalBoundaries!$A:$G,7,0) -> 16970627 | G31: 2
A32: AT-HHStA/443eef51699f3b3af04d0db6cbbe1e5f | B32: AT-HHStA/StudeniceOP | C32: tag:www.monasterium.net,2011:/fond/AT-HHStA/StudeniceOP | D32: Studenice (dt. Studenitz), Dominikanerinnen (1249-1297) | E32: =VLOOKUP($B32,temporalBoundaries!$A:$G,6,0) -> 12491231 | F32: =VLOOKUP($B32,temporalBoundaries!$A:$G,7,0) -> 12971231
A33: AT-HHStA/4c1ae70ca45a80545e3be9c0ce29d73d | B33: AT-HHStA/PolaStMichaelDeMonta | C33: tag:www.monasterium.net,2011:/fond/AT-HHStA/PolaStMichaelDeMonta | D33: St. Michael de Monte bei Pola | E33: =VLOOKUP($B33,temporalBoundaries!$A:$G,6,0) -> 14140806 | F33: =VLOOKUP($B33,temporalBoundaries!$A:$G,7,0) -> 14140806
A34: AT-HHStA/4cf1e40e5a35164d08e67e5d1b282832 | B34: AT-HHStA/StainachOP | C34: tag:www.monasterium.net,2011:/fond/AT-HHStA/StainachOP | D34: Stainach, Dominikanerinnen (1494-1500) | E34: =VLOOKUP($B34,temporalBoundaries!$A:$G,6,0) -> 14940119 | F34: =VLOOKUP($B34,temporalBoundaries!$A:$G,7,0) -> 15009999
A35: AT-HHStA/4ddf289639f88b3f075b379933eeb9d7 | B35: AT-HHStA/BerchtesgadenCanReg | C35: tag:www.monasterium.net,2011:/fond/AT-HHStA/BerchtesgadenCanReg | D35: Berchtesgaden, Augustiner-Chorherren (1202-1460) | E35: =VLOOKUP($B35,temporalBoundaries!$A:$G,6,0) -> 12020608 | F35: =VLOOKUP($B35,temporalBoundaries!$A:$G,7,0) -> 14600329
A36: AT-HHStA/5195563ee7e879397525bf1e2575e57d | B36: AT-HHStA/JudenburgOSCI | C36: tag:www.monasterium.net,2011:/fond/AT-HHStA/JudenburgOSCI | D36: Judenburg, Klarissen (1255-1463) | E36: =VLOOKUP($B36,temporalBoundaries!$A:$G,6,0) -> 14031214 | F36: =VLOOKUP($B36,temporalBoundaries!$A:$G,7,0) -> 14590108
A37: AT-HHStA/5329fc999edb8f67da8d55b09bcaa863 | B37: AT-HHStA/PletrjeOCart | C37: tag:www.monasterium.net,2011:/fond/AT-HHStA/PletrjeOCart | D37: Pletrje (dt. Pletriach), Kartäuser (1450-1472) | E37: =VLOOKUP($B37,temporalBoundaries!$A:$G,6,0) -> 14500601 | F37: =VLOOKUP($B37,temporalBoundaries!$A:$G,7,0) -> 14721224
A38: AT-HHStA/56ea04b6c34e2d1491c3e0b970d01a8a | B38: AT-HHStA/SonnenburgOSB | C38: tag:www.monasterium.net,2011:/fond/AT-HHStA/SonnenburgOSB | D38: Sonnenburg, Benediktiner | E38: =VLOOKUP($B38,temporalBoundaries!$A:$G,6,0) -> 13401008 | F38: =VLOOKUP($B38,temporalBoundaries!$A:$G,7,0) -> 13881021
A39: AT-HHStA/586ca6faa648b2fa6980eb6714c0b1dd | B39: AT-HHStA/WienStClaraOSCI | C39: tag:www.monasterium.net,2011:/fond/AT-HHStA/WienStClaraOSCI | D39: Wien, St. Clara - Klarissen (1302-1568) | E39: =VLOOKUP($B39,temporalBoundaries!$A:$G,6,0) -> 13020329 | F39: =VLOOKUP($B39,temporalBoundaries!$A:$G,7,0) -> 15680227
A40: AT-HHStA/5980e0d609e409ed4e27522ba78b2caa | B40: AT-HHStA/KorneuburgOESA | C40: tag:www.monasterium.net,2011:/fond/AT-HHStA/KorneuburgOESA | D40: Korneuburg, Augustiner-Eremiten (1305-1771) | E40: =VLOOKUP($B40,temporalBoundaries!$A:$G,6,0) -> 13051217 | F40: =VLOOKUP($B40,temporalBoundaries!$A:$G,7,0) -> 17710828
...

Sheet ChartersCount
A1: fondsid | B1: charters | C1: withImages | D1: percentage | E1: from | F1: to | G1: Diff | H1: charters/year | I1: =VLOOKUP($A1,temporalBoundaries!$A$1:$E$470,4,FALSE()) -> Orden | J1: =VLOOKUP($A1,temporalBoundaries!$A$1:$E$470,5,FALSE()) -> m/f | K1: notes
A2: AT-HHStA/WienOFM | B2: 0 | C2: 0 | D2: =100/B2*C2 -> #DIV/0! | E2: =VLOOKUP(A2,temporalBoundaries!$A$2:$G$500,2,FALSE()) -> #VALUE! | F2: =VLOOKUP(A2,temporalBoundaries!$A$2:$G$500,3,FALSE()) -> 0 | G2: =F2-E2 -> #VALUE! | H2: =B2/(G2+1) -> #VALUE! | I2: =VLOOKUP($A2,temporalBoundaries!$A$1:$E$470,4,FALSE()) -> NaN | J2: =VLOOKUP($A2,temporalBoundaries!$A$1:$E$470,5,FALSE()) -> NaN | K2: To check dates
A3: AT-StiAStP/BlUK | B3: 0 | C3: 0 | D3: =100/B3*C3 -> #DIV/0! | E3: =VLOOKUP(A3,temporalBoundaries!$A$2:$G$500,2,FALSE()) -> #VALUE! | F3: =VLOOKUP(A3,temporalBoundaries!$A$2:$G$500,3,FALSE()) -> 0 | G3: =F3-E3 -> #VALUE! | H3: =B3/(G3+1) -> #VALUE! | I3: =VLOOKUP($A3,temporalBoundaries!$A$1:$E$470,4,FALSE()) -> NaN | J3: =VLOOKUP($A3,temporalBoundaries!$A$1:$E$470,5,FALSE()) -> NaN | K3: To check dates
A4: CZ-NA/RK | B4: 0 | C4: 0 | D4: =100/B4*C4 -> #DIV/0! | E4: =VLOOKUP(A4,temporalBoundaries!$A$2:$G$500,2,FALSE()) -> #VALUE! | F4: =VLOOKUP(A4,temporalBoundaries!$A$2:$G$500,3,FALSE()) -> 0 | G4: =F4-E4 -> #VALUE! | H4: =B4/(G4+1) -> #VALUE! | I4: =VLOOKUP($A4,temporalBoundaries!$A$1:$E$470,4,FALSE()) -> NaN | J4: =VLOOKUP($A4,temporalBoundaries!$A$1:$E$470,5,FALSE()) -> NaN | K4: To check dates
A5: CZ-NA/AZK | B5: 0 | C5: 0 | D5: =100/B5*C5 -> #DIV/0! | E5: =VLOOKUP(A5,temporalBoundaries!$A$2:$G$500,2,FALSE()) -> #VALUE! | F5: =VLOOKUP(A5,temporalBoundaries!$A$2:$G$500,3,FALSE()) -> 0 | G5: =F5-E5 -> #VALUE! | H5: =B5/(G5+1) -> #VALUE! | I5: =VLOOKUP($A5,temporalBoundaries!$A$1:$E$470,4,FALSE()) -> NaN | J5: =VLOOKUP($A5,temporalBoundaries!$A$1:$E$470,5,FALSE()) -> NaN | K5: To check dates
A6: CZ-NA/RP | B6: 0 | C6: 0 | D6: =100/B6*C6 -> #DIV/0! | E6: =VLOOKUP(A6,temporalBoundaries!$A$2:$G$500,2,FALSE()) -> #VALUE! | F6: =VLOOKUP(A6,temporalBoundaries!$A$2:$G$500,3,FALSE()) -> 0 | G6: =F6-E6 -> #VALUE! | H6: =B6/(G6+1) -> #VALUE! | I6: =VLOOKUP($A6,temporalBoundaries!$A$1:$E$470,4,FALSE()) -> NaN | J6: =VLOOKUP($A6,temporalBoundaries!$A$1:$E$470,5,FALSE()) -> NaN | K6: To check dates
A7: IT-ASFi/DNFirenzeSIacopo | B7: 0 | C7: 0 | D7: =100/B7*C7 -> #DIV/0! | E7: =VLOOKUP(A7,temporalBoundaries!$A$2:$G$500,2,FALSE()) -> #VALUE! | F7: =VLOOKUP(A7,temporalBoundaries!$A$2:$G$500,3,FALSE()) -> 0 | G7: =F7-E7 -> #VALUE! | H7: =B7/(G7+1) -> #VALUE! | I7: =VLOOKUP($A7,temporalBoundaries!$A$1:$E$470,4,FALSE()) -> NaN | J7: =VLOOKUP($A7,temporalBoundaries!$A$1:$E$470,5,FALSE()) -> NaN | K7: To check dates
A8: IT-ASFi/DNCamaldoli | B8: 0 | C8: 0 | D8: =100/B8*C8 -> #DIV/0! | E8: =VLOOKUP(A8,temporalBoundaries!$A$2:$G$500,2,FALSE()) -> #VALUE! | F8: =VLOOKUP(A8,temporalBoundaries!$A$2:$G$500,3,FALSE()) -> 0 | G8: =F8-E8 -> #VALUE! | H8: =B8/(G8+1) -> #VALUE! | I8: =VLOOKUP($A8,temporalBoundaries!$A$1:$E$470,4,FALSE()) -> NaN | J8: =VLOOKUP($A8,temporalBoundaries!$A$1:$E$470,5,FALSE()) -> NaN | K8: To check dates
A9: IT-ASFi/DNFirenzeSSpirito | B9: 0 | C9: 0 | D9: =100/B9*C9 -> #DIV/0! | E9: =VLOOKUP(A9,temporalBoundaries!$A$2:$G$500,2,FALSE()) -> #VALUE! | F9: =VLOOKUP(A9,temporalBoundaries!$A$2:$G$500,3,FALSE()) -> 0 | G9: =F9-E9 -> #VALUE! | H9: =B9/(G9+1) -> #VALUE! | I9: =VLOOKUP($A9,temporalBoundaries!$A$1:$E$470,4,FALSE()) -> NaN | J9: =VLOOKUP($A9,temporalBoundaries!$A$1:$E$470,5,FALSE()) -> NaN | K9: To check dates
B10: 1 | C10: 1 | D10: =100/B10*C10 -> 100 | E10: =VLOOKUP(A10,temporalBoundaries!$A$2:$G$500,2,FALSE()) -> #N/A | F10: =VLOOKUP(A10,temporalBoundaries!$A$2:$G$500,3,FALSE()) -> #N/A | G10: =F10-E10 -> #N/A | H10: =B10/(G10+1) -> #N/A | I10: =VLOOKUP($A10,temporalBoundaries!$A$1:$E$470,4,FALSE()) -> #N/A | J10: =VLOOKUP($A10,temporalBoundaries!$A$1:$E$470,5,FALSE()) -> #N/A
A11: AT-HHStA/ArnsburgOCist | B11: 1 | C11: 1 | D11: =100/B11*C11 -> 100 | E11: =VLOOKUP(A11,temporalBoundaries!$A$2:$G$500,2,FALSE()) -> 1456 | F11: =VLOOKUP(A11,temporalBoundaries!$A$2:$G$500,3,FALSE()) -> 1456 | G11: =F11-E11 -> 0 | H11: =B11/(G11+1) -> 1 | I11: =VLOOKUP($A11,temporalBoundaries!$A$1:$E$470,4,FALSE()) -> 14560122 | J11: =VLOOKUP($A11,temporalBoundaries!$A$1:$E$470,5,FALSE()) -> 14560122
A12: AT-HHStA/WienStNiklaskloster | B12: 1 | C12: 1 | D12: =100/B12*C12 -> 100 | E12: =VLOOKUP(A12,temporalBoundaries!$A$2:$G$500,2,FALSE()) -> 1434 | F12: =VLOOKUP(A12,temporalBoundaries!$A$2:$G$500,3,FALSE()) -> 1434 | G12: =F12-E12 -> 0 | H12: =B12/(G12+1) -> 1 | I12: =VLOOKUP($A12,temporalBoundaries!$A$1:$E$470,4,FALSE()) -> 14340929 | J12: =VLOOKUP($A12,temporalBoundaries!$A$1:$E$470,5,FALSE()) -> 14340929
A13: AT-HHStA/GrosswardeinOPraem | B13: 1 | C13: 1 | D13: =100/B13*C13 -> 100 | E13: =VLOOKUP(A13,temporalBoundaries!$A$2:$G$500,2,FALSE()) -> 1333 | F13: =VLOOKUP(A13,temporalBoundaries!$A$2:$G$500,3,FALSE()) -> 1333 | G13: =F13-E13 -> 0 | H13: =B13/(G13+1) -> 1 | I13: =VLOOKUP($A13,temporalBoundaries!$A$1:$E$470,4,FALSE()) -> 13330616 | J13: =VLOOKUP($A13,temporalBoundaries!$A$1:$E$470,5,FALSE()) -> 13330616
A14: AT-HHStA/StrebnitzOSB | B14: 1 | C14: 1 | D14: =100/B14*C14 -> 100 | E14: =VLOOKUP(A14,temporalBoundaries!$A$2:$G$500,2,FALSE()) -> 1468 | F14: =VLOOKUP(A14,temporalBoundaries!$A$2:$G$500,3,FALSE()) -> 1468 | G14: =F14-E14 -> 0 | H14: =B14/(G14+1) -> 1 | I14: =VLOOKUP($A14,temporalBoundaries!$A$1:$E$470,4,FALSE()) -> 14680325 | J14: =VLOOKUP($A14,temporalBoundaries!$A$1:$E$470,5,FALSE()) -> 14680325
A15: AT-HHStA/SchnalsOCart | B15: 1 | C15: 1 | D15: =100/B15*C15 -> 100 | E15: =VLOOKUP(A15,temporalBoundaries!$A$2:$G$500,2,FALSE()) -> 1434 | F15: =VLOOKUP(A15,temporalBoundaries!$A$2:$G$500,3,FALSE()) -> 1434 | G15: =F15-E15 -> 0 | H15: =B15/(G15+1) -> 1 | I15: =VLOOKUP($A15,temporalBoundaries!$A$1:$E$470,4,FALSE()) -> 14340531 | J15: =VLOOKUP($A15,temporalBoundaries!$A$1:$E$470,5,FALSE()) -> 14340531
A16: AT-HHStA/PolaStMichaelDeMonta | B16: 1 | C16: 1 | D16: =100/B16*C16 -> 100 | E16: =VLOOKUP(A16,temporalBoundaries!$A$2:$G$500,2,FALSE()) -> 1414 | F16: =VLOOKUP(A16,temporalBoundaries!$A$2:$G$500,3,FALSE()) -> 1414 | G16: =F16-E16 -> 0 | H16: =B16/(G16+1) -> 1 | I16: =VLOOKUP($A16,temporalBoundaries!$A$1:$E$470,4,FALSE()) -> 14140806 | J16: =VLOOKUP($A16,temporalBoundaries!$A$1:$E$470,5,FALSE()) -> 14140806
A17: AT-HHStA/SbgFrauenklosterStPeter | B17: 1 | C17: 1 | D17: =100/B17*C17 -> 100 | E17: =VLOOKUP(A17,temporalBoundaries!$A$2:$G$500,2,FALSE()) -> 1416 | F17: =VLOOKUP(A17,temporalBoundaries!$A$2:$G$500,3,FALSE()) -> 1416 | G17: =F17-E17 -> 0 | H17: =B17/(G17+1) -> 1 | I17: =VLOOKUP($A17,temporalBoundaries!$A$1:$E$470,4,FALSE()) -> 14160424 | J17: =VLOOKUP($A17,temporalBoundaries!$A$1:$E$470,5,FALSE()) -> 14160424
A18: AT-HHStA/FreudnitzOCart | B18: 1 | C18: 1 | D18: =100/B18*C18 -> 100 | E18: =VLOOKUP(A18,temporalBoundaries!$A$2:$G$500,2,FALSE()) -> 1618 | F18: =VLOOKUP(A18,temporalBoundaries!$A$2:$G$500,3,FALSE()) -> 1618 | G18: =F18-E18 -> 0 | H18: =B18/(G18+1) -> 1 | I18: =VLOOKUP($A18,temporalBoundaries!$A$1:$E$470,4,FALSE()) -> 16180916 | J18: =VLOOKUP($A18,temporalBoundaries!$A$1:$E$470,5,FALSE()) -> 16180916
A19: AT-HHStA/LindauCan | B19: 1 | C19: 1 | D19: =100/B19*C19 -> 100 | E19: =VLOOKUP(A19,temporalBoundaries!$A$2:$G$500,2,FALSE()) -> 839 | F19: =VLOOKUP(A19,temporalBoundaries!$A$2:$G$500,3,FALSE()) -> 839 | G19: =F19-E19 -> 0 | H19: =B19/(G19+1) -> 1 | I19: =VLOOKUP($A19,temporalBoundaries!$A$1:$E$470,4,FALSE()) -> 8390421 | J19: =VLOOKUP($A19,temporalBoundaries!$A$1:$E$470,5,FALSE()) -> 8390421
A20: AT-HHStA/OssiachOSB | B20: 1 | C20: 1 | D20: =100/B20*C20 -> 100 | E20: =VLOOKUP(A20,temporalBoundaries!$A$2:$G$500,2,FALSE()) -> 1317 | F20: =VLOOKUP(A20,temporalBoundaries!$A$2:$G$500,3,FALSE()) -> 1317 | G20: =F20-E20 -> 0 | H20: =B20/(G20+1) -> 1 | I20: =VLOOKUP($A20,temporalBoundaries!$A$1:$E$470,4,FALSE()) -> 13170829 | J20: =VLOOKUP($A20,temporalBoundaries!$A$1:$E$470,5,FALSE()) -> 13170829
A21: AT-HHStA/FriesachOSA | B21: 1 | C21: 1 | D21: =100/B21*C21 -> 100 | E21: =VLOOKUP(A21,temporalBoundaries!$A$2:$G$500,2,FALSE()) -> 1499 | F21: =VLOOKUP(A21,temporalBoundaries!$A$2:$G$500,3,FALSE()) -> 1499 | G21: =F21-E21 -> 0 | H21: =B21/(G21+1) -> 1 | I21: =VLOOKUP($A21,temporalBoundaries!$A$1:$E$470,4,FALSE()) -> 14990913 | J21: =VLOOKUP($A21,temporalBoundaries!$A$1:$E$470,5,FALSE()) -> 14990913
A22: AT-HHStA/TraunseeOSB | B22: 1 | C22: 1 | D22: =100/B22*C22 -> 100 | E22: =VLOOKUP(A22,temporalBoundaries!$A$2:$G$500,2,FALSE()) -> 909 | F22: =VLOOKUP(A22,temporalBoundaries!$A$2:$G$500,3,FALSE()) -> 909 | G22: =F22-E22 -> 0 | H22: =B22/(G22+1) -> 1 | I22: =VLOOKUP($A22,temporalBoundaries!$A$1:$E$470,4,FALSE()) -> 9090219 | J22: =VLOOKUP($A22,temporalBoundaries!$A$1:$E$470,5,FALSE()) -> 9090219
... A236: CZ-MZA/E51 | B236: 45 | C236: 27 | D236: =100/B236*C236 -> 60 | E236: =VLOOKUP(A236,temporalBoundaries!$A$2:$G$500,2,FALSE()) -> 1669 | F236: =VLOOKUP(A236,temporalBoundaries!$A$2:$G$500,3,FALSE()) -> 1741 | G236: =F236-E236 -> 72 | H236: =B236/(G236+1) -> 0.61643836 | I236: =VLOOKUP($A236,temporalBoundaries!$A$1:$E$470,4,FALSE()) -> 16690327 | J236: =VLOOKUP($A236,temporalBoundaries!$A$1:$E$470,5,FALSE()) -> 17410217
A237: AT-HHStA/ZiceOCar | B237: 45 | C237: 0 | D237: =100/B237*C237 -> 0 | E237: =VLOOKUP(A237,temporalBoundaries!$A$2:$G$500,2,FALSE()) -> 1240 | F237: =VLOOKUP(A237,temporalBoundaries!$A$2:$G$500,3,FALSE()) -> 1240 | G237: =F237-E237 -> 0 | H237: =B237/(G237+1) -> 45 | I237: =VLOOKUP($A237,temporalBoundaries!$A$1:$E$470,4,FALSE()) -> 12409999 | J237: =VLOOKUP($A237,temporalBoundaries!$A$1:$E$470,5,FALSE()) -> 12409999 | K237: To check dates
A238: IT-ASFi/DNPratoSVincenzo | B238: 46 | C238: 0 | D238: =100/B238*C238 -> 0 | E238: =VLOOKUP(A238,temporalBoundaries!$A$2:$G$500,2,FALSE()) -> 1328 | F238: =VLOOKUP(A238,temporalBoundaries!$A$2:$G$500,3,FALSE()) -> 1398 | G238: =F238-E238 -> 70 | H238: =B238/(G238+1) -> 0.64788732 | I238: =VLOOKUP($A238,temporalBoundaries!$A$1:$E$470,4,FALSE()) -> 13280201 | J238: =VLOOKUP($A238,temporalBoundaries!$A$1:$E$470,5,FALSE()) -> 13981215
A239: IT-ASFi/DNPistoiaSFrancesco | B239: 47 | C239: 0 | D239: =100/B239*C239 -> 0 | E239: =VLOOKUP(A239,temporalBoundaries!$A$2:$G$500,2,FALSE()) -> 1255 | F239: =VLOOKUP(A239,temporalBoundaries!$A$2:$G$500,3,FALSE()) -> 1398 | G239: =F239-E239 -> 143 | H239: =B239/(G239+1) -> 0.32638889 | I239: =VLOOKUP($A239,temporalBoundaries!$A$1:$E$470,4,FALSE()) -> 12551212 | J239: =VLOOKUP($A239,temporalBoundaries!$A$1:$E$470,5,FALSE()) -> 13981219
A240: AT-AWMK/AsparnOFMConv | B240: 48 | C240: 48 | D240: =100/B240*C240 -> 100 | E240: =VLOOKUP(A240,temporalBoundaries!$A$2:$G$500,2,FALSE()) -> 1471 | F240: =VLOOKUP(A240,temporalBoundaries!$A$2:$G$500,3,FALSE()) -> 1767 | G240: =F240-E240 -> 296 | H240: =B240/(G240+1) -> 0.16161616 | I240: =VLOOKUP($A240,temporalBoundaries!$A$1:$E$470,4,FALSE()) -> 14711127 | J240: =VLOOKUP($A240,temporalBoundaries!$A$1:$E$470,5,FALSE()) -> 17670520
A241: IT-ASFi/DNPratoSNiccolo | B241: 49 | C241: 0 | D241: =100/B241*C241 -> 0 | E241: =VLOOKUP(A241,temporalBoundaries!$A$2:$G$500,2,FALSE()) -> 1282 | F241: =VLOOKUP(A241,temporalBoundaries!$A$2:$G$500,3,FALSE()) -> 1385 | G241: =F241-E241 -> 103 | H241: =B241/(G241+1) -> 0.47115385 | I241: =VLOOKUP($A241,temporalBoundaries!$A$1:$E$470,4,FALSE()) -> 12820926 | J241: =VLOOKUP($A241,temporalBoundaries!$A$1:$E$470,5,FALSE()) -> 13850429
A242: IT-ASBa/ASBa_SGiac-strum | B242: 50 | C242: 50 | D242: =100/B242*C242 -> 100 | E242: =VLOOKUP(A242,temporalBoundaries!$A$2:$G$500,2,FALSE()) -> 1550 | F242: =VLOOKUP(A242,temporalBoundaries!$A$2:$G$500,3,FALSE()) -> 1680 | G242: =F242-E242 -> 130 | H242: =B242/(G242+1) -> 0.38167939 | I242: =VLOOKUP($A242,temporalBoundaries!$A$1:$E$470,4,FALSE()) -> 15500922 | J242: =VLOOKUP($A242,temporalBoundaries!$A$1:$E$470,5,FALSE()) -> 16800301
A243: IT-ASFi/DNFirenzeSMariaSulPrato | B243: 51 | C243: 0 | D243: =100/B243*C243 -> 0 | E243: =VLOOKUP(A243,temporalBoundaries!$A$2:$G$500,2,FALSE()) -> 1216 | F243: =VLOOKUP(A243,temporalBoundaries!$A$2:$G$500,3,FALSE()) -> 1394 | G243: =F243-E243 -> 178 | H243: =B243/(G243+1) -> 0.2849162 | I243: =VLOOKUP($A243,temporalBoundaries!$A$1:$E$470,4,FALSE()) -> 12160419 | J243: =VLOOKUP($A243,temporalBoundaries!$A$1:$E$470,5,FALSE()) -> 13940625
A244: HU-PBFL/TihanyOSB | B244: 53 | C244: 42 | D244: =100/B244*C244 -> 79.245283 | E244: =VLOOKUP(A244,temporalBoundaries!$A$2:$G$500,2,FALSE()) -> 1055 | F244: =VLOOKUP(A244,temporalBoundaries!$A$2:$G$500,3,FALSE()) -> 1522 | G244: =F244-E244 -> 467 | H244: =B244/(G244+1) -> 0.11324786 | I244: =VLOOKUP($A244,temporalBoundaries!$A$1:$E$470,4,FALSE()) -> 10551231 | J244: =VLOOKUP($A244,temporalBoundaries!$A$1:$E$470,5,FALSE()) -> 15220916
A245: CZ-NA/AZK%7CKladruby | B245: 53 | C245: 53 | D245: =100/B245*C245 -> 100 | E245: =VLOOKUP(A245,temporalBoundaries!$A$2:$G$500,2,FALSE()) -> 1115 | F245: =VLOOKUP(A245,temporalBoundaries!$A$2:$G$500,3,FALSE()) -> 1526 | G245: =F245-E245 -> 411 | H245: =B245/(G245+1) -> 0.12864078 | I245: =VLOOKUP($A245,temporalBoundaries!$A$1:$E$470,4,FALSE()) -> 11151231 | J245: =VLOOKUP($A245,temporalBoundaries!$A$1:$E$470,5,FALSE()) -> 15261123
A246: IT-ASFi/DNPistoiaSMariaDegliAngioli | B246: 54 | C246: 0 | D246: =100/B246*C246 -> 0 | E246: =VLOOKUP(A246,temporalBoundaries!$A$2:$G$500,2,FALSE()) -> 1100 | F246: =VLOOKUP(A246,temporalBoundaries!$A$2:$G$500,3,FALSE()) -> 1397 | G246: =F246-E246 -> 297 | H246: =B246/(G246+1) -> 0.18120805 | I246: =VLOOKUP($A246,temporalBoundaries!$A$1:$E$470,4,FALSE()) -> 11001130 | J246: =VLOOKUP($A246,temporalBoundaries!$A$1:$E$470,5,FALSE()) -> 13970925
A247: CZ-ZAO/RKL-OPAVA | B247: 55 | C247: 55 | D247: =100/B247*C247 -> 100 | E247: =VLOOKUP(A247,temporalBoundaries!$A$2:$G$500,2,FALSE()) -> 1289 | F247: =VLOOKUP(A247,temporalBoundaries!$A$2:$G$500,3,FALSE()) -> 1704 | G247: =F247-E247 -> 415 | H247: =B247/(G247+1) -> 0.13221154 | I247: =VLOOKUP($A247,temporalBoundaries!$A$1:$E$470,4,FALSE()) -> 12899999 | J247: =VLOOKUP($A247,temporalBoundaries!$A$1:$E$470,5,FALSE()) -> 17040910
A248: CZ-NA/AZK%7CLitomysl | B248: 55 | C248: 55 | D248: =100/B248*C248 -> 100 | E248: =VLOOKUP(A248,temporalBoundaries!$A$2:$G$500,2,FALSE()) -> 1167 | F248: =VLOOKUP(A248,temporalBoundaries!$A$2:$G$500,3,FALSE()) -> 1501 | G248: =F248-E248 -> 334 | H248: =B248/(G248+1) -> 0.1641791 | I248: =VLOOKUP($A248,temporalBoundaries!$A$1:$E$470,4,FALSE()) -> 11670120 | J248: =VLOOKUP($A248,temporalBoundaries!$A$1:$E$470,5,FALSE()) -> 15010710
A249: CZ-MZA/E58 | B249: 56 | C249: 53 | D249: =100/B249*C249 -> 94.642857 | E249: =VLOOKUP(A249,temporalBoundaries!$A$2:$G$500,2,FALSE()) -> 1258 | F249: =VLOOKUP(A249,temporalBoundaries!$A$2:$G$500,3,FALSE()) -> 1841 | G249: =F249-E249 -> 583 | H249: =B249/(G249+1) -> 0.095890411 | I249: =VLOOKUP($A249,temporalBoundaries!$A$1:$E$470,4,FALSE()) -> 12580223 | J249: =VLOOKUP($A249,temporalBoundaries!$A$1:$E$470,5,FALSE()) -> 18411228
... A264: DE-UAHD/AlzeyAugustinerkloster | B264: 66 | C264: 66 | D264: =100/B264*C264 -> 100 | E264: =VLOOKUP(A264,temporalBoundaries!$A$2:$G$500,2,FALSE()) -> 1393 | F264: =VLOOKUP(A264,temporalBoundaries!$A$2:$G$500,3,FALSE()) -> 1551 | G264: =F264-E264 -> 158 | H264: =B264/(G264+1) -> 0.41509434 | I264: =VLOOKUP($A264,temporalBoundaries!$A$1:$E$470,4,FALSE()) -> 13930615 | J264: =VLOOKUP($A264,temporalBoundaries!$A$1:$E$470,5,FALSE()) -> 15510218
A265: CZ-NA/AZK%7CPohled | B265: 66 | C265: 66 | D265: =100/B265*C265 -> 100 | E265: =VLOOKUP(A265,temporalBoundaries!$A$2:$G$500,2,FALSE()) -> 1336 | F265: =VLOOKUP(A265,temporalBoundaries!$A$2:$G$500,3,FALSE()) -> 1336 | G265: =F265-E265 -> 0 | H265: =B265/(G265+1) -> 66 | I265: =VLOOKUP($A265,temporalBoundaries!$A$1:$E$470,4,FALSE()) -> 13360312 | J265: =VLOOKUP($A265,temporalBoundaries!$A$1:$E$470,5,FALSE()) -> 13360312 | K265: To check dates
A266: IT-ASFi/DNPinelli | B266: 68 | C266: 0 | D266: =100/B266*C266 -> 0 | E266: =VLOOKUP(A266,temporalBoundaries!$A$2:$G$500,2,FALSE()) -> 1295 | F266: =VLOOKUP(A266,temporalBoundaries!$A$2:$G$500,3,FALSE()) -> 1398 | G266: =F266-E266 -> 103 | H266: =B266/(G266+1) -> 0.65384615 | I266: =VLOOKUP($A266,temporalBoundaries!$A$1:$E$470,4,FALSE()) -> 12951006 | J266: =VLOOKUP($A266,temporalBoundaries!$A$1:$E$470,5,FALSE()) -> 13980114
A267: AT-VLA/ValdunaKl | B267: 69 | C267: 67 | D267: =100/B267*C267 -> 97.101449 | E267: =VLOOKUP(A267,temporalBoundaries!$A$2:$G$500,2,FALSE()) -> 1395 | F267: =VLOOKUP(A267,temporalBoundaries!$A$2:$G$500,3,FALSE()) -> 1715 | G267: =F267-E267 -> 320 | H267: =B267/(G267+1) -> 0.21495327 | I267: =VLOOKUP($A267,temporalBoundaries!$A$1:$E$470,4,FALSE()) -> 13950529 | J267: =VLOOKUP($A267,temporalBoundaries!$A$1:$E$470,5,FALSE()) -> 17151101
...

Sheet temporalBoundaries
A1: fondsid | B1: from_year | C1: to_year | D1: Orden | E1: m/f | F1: from | G1: to | H1: Diff | I1: ToDo
A2: AT-StiARein/ReinOCist | B2: =FLOOR(F2/1000,1) -> 10 | D2: =VLOOKUP(A2,fonds!$B$2:$F$495,4,FALSE()) -> 10000 | E2: =VLOOKUP($A2,fonds!$B$2:$F$495,5,FALSE()) -> 16001223 | F2: 10000 | G2: 16001223 | H2: =G2-F2 -> 15991223 | I2: To Clean up
A3: DE-BayHStA/KUFrauenchiemsee | B3: =FLOOR(F3/1000,1) -> 1640 | D3: =VLOOKUP(A3,fonds!$B$2:$F$495,4,FALSE()) -> 1640729 | E3: =VLOOKUP($A3,fonds!$B$2:$F$495,5,FALSE()) -> 17930129 | F3: 1640729 | G3: 17930129 | H3: =G3-F3 -> 16289400 | I3: To Clean up
A4: IT-ASFi/DNPistoiaSBartolomeo | B4: =FLOOR(F4/10000,1) -> 748 | C4: =FLOOR(G4/10000,1) -> 1398 | D4: =VLOOKUP(A4,fonds!$B$2:$F$495,4,FALSE()) -> 7480908 | E4: =VLOOKUP($A4,fonds!$B$2:$F$495,5,FALSE()) -> 13980413 | F4: 7480908 | G4: 13980413 | H4: =G4-F4 -> 6499505
A5: IT-ASFi/DNVallombrosaSMariaDAcquabella | B5: =FLOOR(F5/10000,1) -> 790 | C5: =FLOOR(G5/10000,1) -> 1398 | D5: =VLOOKUP(A5,fonds!$B$2:$F$495,4,FALSE()) -> 7900714 | E5: =VLOOKUP($A5,fonds!$B$2:$F$495,5,FALSE()) -> 13980723 | F5: 7900714 | G5: 13980723 | H5: =G5-F5 -> 6080009
A6: DE-BayHStA/KUNiederaltaich | B6: =FLOOR(F6/10000,1) -> 790 | C6: =FLOOR(G6/10000,1) -> 1801 | D6: =VLOOKUP(A6,fonds!$B$2:$F$495,4,FALSE()) -> 7909999 | E6: =VLOOKUP($A6,fonds!$B$2:$F$495,5,FALSE()) -> 18011031 | F6: 7909999 | G6: 18011031 | H6: =G6-F6 -> 10101032
A7: DE-BayHStA/KURegensburgStEmmeram | B7: =FLOOR(F7/10000,1) -> 794 | C7: =FLOOR(G7/10000,1) -> 1800 | D7: =VLOOKUP(A7,fonds!$B$2:$F$495,4,FALSE()) -> 7940222 | E7: =VLOOKUP($A7,fonds!$B$2:$F$495,5,FALSE()) -> 18000125 | F7: 7940222 | G7: 18000125 | H7: =G7-F7 -> 10059903
A8: IT-ASFi/DNFirenzeSFrediano | B8: =FLOOR(F8/10000,1) -> 816 | C8: =FLOOR(G8/10000,1) -> 1398 | D8: =VLOOKUP(A8,fonds!$B$2:$F$495,4,FALSE()) -> 8161117 | E8: =VLOOKUP($A8,fonds!$B$2:$F$495,5,FALSE()) -> 13981114 | F8: 8161117 | G8: 13981114 | H8: =G8-F8 -> 5819997
A9: AT-HHStA/LindauCan | B9: =FLOOR(F9/10000,1) -> 839 | C9: =FLOOR(G9/10000,1) -> 839 | D9: =VLOOKUP(A9,fonds!$B$2:$F$495,4,FALSE()) -> 8390421 | E9: =VLOOKUP($A9,fonds!$B$2:$F$495,5,FALSE()) -> 8390421 | F9: 8390421 | G9: 8390421 | H9: =G9-F9 -> 0
A10: AT-StiAMt/MattseeCan | B10: =FLOOR(F10/10000,1) -> 860 | C10: =FLOOR(G10/10000,1) -> 1400 | D10: =VLOOKUP(A10,fonds!$B$2:$F$495,4,FALSE()) -> 8600508 | E10: =VLOOKUP($A10,fonds!$B$2:$F$495,5,FALSE()) -> 14001129 | F10: 8600508 | G10: 14001129 | H10: =G10-F10 -> 5400621
A11: CH-StiASG/StiAPfae | B11: =FLOOR(F11/10000,1) -> 861 | C11: =FLOOR(G11/10000,1) -> 1500 | D11: =VLOOKUP(A11,fonds!$B$2:$F$495,4,FALSE()) -> 8610306 | E11: =VLOOKUP($A11,fonds!$B$2:$F$495,5,FALSE()) -> 15001103 | F11: 8610306 | G11: 15001103 | H11: =G11-F11 -> 6390797
A12: IT-ASFi/DNPassignanoSMichele | B12: =FLOOR(F12/10000,1) -> 884 | C12: =FLOOR(G12/10000,1) -> 1390 | D12: =VLOOKUP(A12,fonds!$B$2:$F$495,4,FALSE()) -> 8840331 | E12: =VLOOKUP($A12,fonds!$B$2:$F$495,5,FALSE()) -> 13900930 | F12: 8840331 | G12: 13900930 | H12: =G12-F12 -> 5060599
A13: ES-AHN/MonasterioSanSalvadordeLerez | B13: =FLOOR(F13/10000,1) -> 886 | C13: =FLOOR(G13/10000,1) -> 1600 | D13: =VLOOKUP(A13,fonds!$B$2:$F$495,4,FALSE()) -> 8860817 | E13: =VLOOKUP($A13,fonds!$B$2:$F$495,5,FALSE()) -> 16000621 | F13: 8860817 | G13: 16000621 | H13: =G13-F13 -> 7139804
A14: AT-HHStA/TraunseeOSB | B14: =FLOOR(F14/10000,1) -> 909 | C14: =FLOOR(G14/10000,1) -> 909 | D14: =VLOOKUP(A14,fonds!$B$2:$F$495,4,FALSE()) -> 9090219 | E14: =VLOOKUP($A14,fonds!$B$2:$F$495,5,FALSE()) -> 9090219 | F14: 9090219 | G14: 9090219 | H14: =G14-F14 -> 0 | I14: To Clean up
A15: IT-ASNA/SGA | B15: =FLOOR(F15/10000,1) -> 911 | C15: =FLOOR(G15/10000,1) -> 1675 | D15: =VLOOKUP(A15,fonds!$B$2:$F$495,4,FALSE()) -> 9110327 | E15: =VLOOKUP($A15,fonds!$B$2:$F$495,5,FALSE()) -> 16750108 | F15: 9110327 | G15: 16750108 | H15: =G15-F15 -> 7639781
A16: ES-AHN/MonasterioSantoEstevo | B16: =FLOOR(F16/10000,1) -> 921 | C16: =FLOOR(G16/10000,1) -> 1686 | D16: =VLOOKUP(A16,fonds!$B$2:$F$495,4,FALSE()) -> 9211012 | E16: =VLOOKUP($A16,fonds!$B$2:$F$495,5,FALSE()) -> 16860820 | F16: 9211012 | G16: 16860820 | H16: =G16-F16 -> 7649808
A17: IT-ASFi/DNColtibuonoSLorenzo | B17: =FLOOR(F17/10000,1) -> 943 | C17: =FLOOR(G17/10000,1) -> 1398 | D17: =VLOOKUP(A17,fonds!$B$2:$F$495,4,FALSE()) -> 9431231 | E17: =VLOOKUP($A17,fonds!$B$2:$F$495,5,FALSE()) -> 13980809 | F17: 9431231 | G17: 13980809 | H17: =G17-F17 -> 4549578
A18: IT-ASFi/DNPistoiaSMercuriale | B18: =FLOOR(F18/10000,1) -> 945 | C18: =FLOOR(G18/10000,1) -> 1395 | D18: =VLOOKUP(A18,fonds!$B$2:$F$495,4,FALSE()) -> 9451115 | E18: =VLOOKUP($A18,fonds!$B$2:$F$495,5,FALSE()) -> 13950108 | F18: 9451115 | G18: 13950108 | H18: =G18-F18 -> 4498993
A19: ES-AHN/MonasterioSanSalvadordeCelanova | B19: =FLOOR(F19/10000,1) -> 951 | C19: =FLOOR(G19/10000,1) -> 1631 | D19: =VLOOKUP(A19,fonds!$B$2:$F$495,4,FALSE()) -> 9510825 | E19: =VLOOKUP($A19,fonds!$B$2:$F$495,5,FALSE()) -> 16310717 | F19: 9510825 | G19: 16310717 | H19: =G19-F19 -> 6799892
A20: IT-ASFi/DNFirenzeSMiniato | B20: =FLOOR(F20/10000,1) -> 960 | C20: =FLOOR(G20/10000,1) -> 1398 | D20: =VLOOKUP(A20,fonds!$B$2:$F$495,4,FALSE()) -> 9600424 | E20: =VLOOKUP($A20,fonds!$B$2:$F$495,5,FALSE()) -> 13981017 | F20: 9600424 | G20: 13981017 | H20: =G20-F20 -> 4380593
A21: ES-AHN/MonasterioSantaMariaMelon | B21: =FLOOR(F21/10000,1) -> 963 | C21: =FLOOR(G21/10000,1) -> 1717 | D21: =VLOOKUP(A21,fonds!$B$2:$F$495,4,FALSE()) -> 9630624 | E21: =VLOOKUP($A21,fonds!$B$2:$F$495,5,FALSE()) -> 17170605 | F21: 9630624 | G21: 17170605 | H21: =G21-F21 -> 7539981
A22: IT-ASFi/DNFirenzeSMariaDellaBadia | B22: =FLOOR(F22/10000,1) -> 969 | C22: =FLOOR(G22/10000,1) -> 1398 | D22: =VLOOKUP(A22,fonds!$B$2:$F$495,4,FALSE()) -> 9690708 | E22: =VLOOKUP($A22,fonds!$B$2:$F$495,5,FALSE()) -> 13981227 | F22: 9690708 | G22: 13981227 | H22: =G22-F22 -> 4290519
A23: HR-DAZD/336 | B23: =FLOOR(F23/10000,1) -> 986 | C23: =FLOOR(G23/10000,1) -> 1377 | D23: =VLOOKUP(A23,fonds!$B$2:$F$495,4,FALSE()) -> 9861219 | E23: =VLOOKUP($A23,fonds!$B$2:$F$495,5,FALSE()) -> 13770510 | F23: 9861219 | G23: 13770510 | H23: =G23-F23 -> 3909291
A24: IT-ASFi/DNFirenzeSApollonia | B24: =FLOOR(F24/10000,1) -> 989 | C24: =FLOOR(G24/10000,1) -> 1398 | D24: =VLOOKUP(A24,fonds!$B$2:$F$495,4,FALSE()) -> 9890331 | E24: =VLOOKUP($A24,fonds!$B$2:$F$495,5,FALSE()) -> 13981016 | F24: 9890331 | G24: 13981016 | H24: =G24-F24 -> 4090685
A25: CZ-NA/RBB | B25: =FLOOR(F25/10000,1) -> 993 | C25: =FLOOR(G25/10000,1) -> 1948 | D25: =VLOOKUP(A25,fonds!$B$2:$F$495,4,FALSE()) -> 9930114 | E25: =VLOOKUP($A25,fonds!$B$2:$F$495,5,FALSE()) -> 19480408 | F25: 9930114 | G25: 19480408 | H25: =G25-F25 -> 9550294
A26: AT-StiAL/LambachOSB | B26: =FLOOR(F26/10000,1) -> 993 | C26: =FLOOR(G26/10000,1) -> 1600 | D26: =VLOOKUP(A26,fonds!$B$2:$F$495,4,FALSE()) -> 9931231 | E26: =VLOOKUP($A26,fonds!$B$2:$F$495,5,FALSE()) -> 16001211 | F26: 9931231 | G26: 16001211 | H26: =G26-F26 -> 6069980
... A29: DE-BAH/UrkStMi | B29: =FLOOR(F29/10000,1) -> 1001 | C29: =FLOOR(G29/10000,1) -> 1801 | D29: =VLOOKUP(A29,fonds!$B$2:$F$495,4,FALSE()) -> 10019999 | E29: =VLOOKUP($A29,fonds!$B$2:$F$495,5,FALSE()) -> 18010602 | F29: 10019999 | G29: 18010602 | H29: =G29-F29 -> 7990603
A30: AT-StiASF/StFlorianCanReg | B30: =FLOOR(F30/10000,1) -> 1002 | C30: =FLOOR(G30/10000,1) -> 1002 | D30: =VLOOKUP(A30,fonds!$B$2:$F$495,4,FALSE()) -> 10020720 | E30: =VLOOKUP($A30,fonds!$B$2:$F$495,5,FALSE()) -> 10020720 | F30: 10020720 | G30: 10020720 | H30: =G30-F30 -> 0 | I30: To Clean up
A31: AT-StiAK/KlosterneuburgCanReg | B31: =FLOOR(F31/10000,1) -> 1002 | C31: =FLOOR(G31/10000,1) -> 1730 | D31: =VLOOKUP(A31,fonds!$B$2:$F$495,4,FALSE()) -> 10021101 | E31: =VLOOKUP($A31,fonds!$B$2:$F$495,5,FALSE()) -> 17300613 | F31: 10021101 | G31: 17300613 | H31: =G31-F31 -> 7279512
A32: AT-StiASP/Urkunden | B32: =FLOOR(F32/10000,1) -> 1005 | C32: =FLOOR(G32/10000,1) -> 1981 | D32: =VLOOKUP(A32,fonds!$B$2:$F$495,4,FALSE()) -> 10051207 | E32: =VLOOKUP($A32,fonds!$B$2:$F$495,5,FALSE()) -> 19810403 | F32: 10051207 | G32: 19810403 | H32: =G32-F32 -> 9759196
A33: AT-StiAAdm/Urkunden | B33: =FLOOR(F33/10000,1) -> 1006 | C33: =FLOOR(G33/10000,1) -> 1908 | D33: =VLOOKUP(A33,fonds!$B$2:$F$495,4,FALSE()) -> 10061207 | E33: =VLOOKUP($A33,fonds!$B$2:$F$495,5,FALSE()) -> 19080724 | F33: 10061207 | G33: 19080724 | H33: =G33-F33 -> 9019517
A34: ES-AHN/MonasterioSanPedroRocas | B34: =FLOOR(F34/10000,1) -> 1007 | C34: =FLOOR(G34/10000,1) -> 1486 | D34: =VLOOKUP(A34,fonds!$B$2:$F$495,4,FALSE()) -> 10070423 | E34: =VLOOKUP($A34,fonds!$B$2:$F$495,5,FALSE()) -> 14860109 | F34: 10070423 | G34: 14860109 | H34: =G34-F34 -> 4789686
A35: DE-StAW/StAlbanCan | B35: =FLOOR(F35/10000,1) -> 1007 | C35: =FLOOR(G35/10000,1) -> 1761 | D35: =VLOOKUP(A35,fonds!$B$2:$F$495,4,FALSE()) -> 10070527 | E35: =VLOOKUP($A35,fonds!$B$2:$F$495,5,FALSE()) -> 17610530 | F35: 10070527 | G35: 17610530 | H35: =G35-F35 -> 7540003
A36: IT-ASFi/DNRipoliSBartolomeo | B36: =FLOOR(F36/10000,1) -> 1007 | C36: =FLOOR(G36/10000,1) -> 1398 | D36: =VLOOKUP(A36,fonds!$B$2:$F$495,4,FALSE()) -> 10070930 | E36: =VLOOKUP($A36,fonds!$B$2:$F$495,5,FALSE()) -> 13981206 | F36: 10070930 | G36: 13981206 | H36: =G36-F36 -> 3910276
A37: DE-BayHStA/KUPassauNiedernburg | B37: =FLOOR(F37/10000,1) -> 1010 | C37: =FLOOR(G37/10000,1) -> 1801 | D37: =VLOOKUP(A37,fonds!$B$2:$F$495,4,FALSE()) -> 10100419 | E37: =VLOOKUP($A37,fonds!$B$2:$F$495,5,FALSE()) -> 18010521 | F37: 10100419 | G37: 18010521 | H37: =G37-F37 -> 7910102
A38: IT-ASFi/DNRosanoSmaAnnunziata | B38: =FLOOR(F38/10000,1) -> 1015 | C38: =FLOOR(G38/10000,1) -> 1398 | D38: =VLOOKUP(A38,fonds!$B$2:$F$495,4,FALSE()) -> 10150531 | E38: =VLOOKUP($A38,fonds!$B$2:$F$495,5,FALSE()) -> 13980413 | F38: 10150531 | G38: 13980413 | H38: =G38-F38 -> 3829882
A39: IT-BSNSP/16-Napoli_monasteri_di_S_Gregorio_S_Arcangelo_a_Baiano_e_S_Martino | B39: =FLOOR(F39/10000,1) -> 1015 | C39: =FLOOR(G39/10000,1) -> 1717 | D39: =VLOOKUP(A39,fonds!$B$2:$F$495,4,FALSE()) -> 10150601 | E39: =VLOOKUP($A39,fonds!$B$2:$F$495,5,FALSE()) -> 17170320 | F39: 10150601 | G39: 17170320 | H39: =G39-F39 -> 7019719
A40: IT-ASFi/DNFiesoleSBartolomeo | B40: =FLOOR(F40/10000,1) -> 1017 | C40: =FLOOR(G40/10000,1) -> 1394 | D40: =VLOOKUP(A40,fonds!$B$2:$F$495,4,FALSE()) -> 10170630 | E40: =VLOOKUP($A40,fonds!$B$2:$F$495,5,FALSE()) -> 13941227 | F40: 10170630 | G40: 13941227 | H40: =G40-F40 -> 3770597
A41: IT-ASFi/DNPistoiaSBenedetto | B41: =FLOOR(F41/10000,1) -> 1019 | C41: =FLOOR(G41/10000,1) -> 1398 | D41: =VLOOKUP(A41,fonds!$B$2:$F$495,4,FALSE()) -> 10191213 | E41: =VLOOKUP($A41,fonds!$B$2:$F$495,5,FALSE()) -> 13981223 | F41: 10191213 | G41: 13981223 | H41: =G41-F41 -> 3790010
A42: ES-AHN/MonasterioSantaMariadeOseira | B42: =FLOOR(F42/10000,1) -> 1025 | C42: =FLOOR(G42/10000,1) -> 1680 | D42: =VLOOKUP(A42,fonds!$B$2:$F$495,4,FALSE()) -> 10250831 | E42: =VLOOKUP($A42,fonds!$B$2:$F$495,5,FALSE()) -> 16800415 | F42: 10250831 | G42: 16800415 | H42: =G42-F42 -> 6549584
...

Sheet temporalBoundariesGraph

Sheet settlements
A1: Settlement | B1: specification | C1: additioanl | D1: md5 | E1: =VLOOKUP(D1,fonds!$A$1:$B$495,2,FALSE()) -> fondsid | F1: geonameId | G1: lat | H1: lng | I1: name | J1: fcode | K1: adminName1 | L1: corrected | M1: Comment
A2: S. Maria della Grotta | C2: (3 AA I - 4 BB V) | D2: IT-BSNSP/37b021aef54bc81e7b3e04fb195782f7 | E2: =VLOOKUP(D2,fonds!$A$1:$B$495,2,FALSE()) -> IT-BSNSP/08-S_Maria_della_Grotta | F2: 12188697 | G2: 4119284 | H2: 146161 | I2: Abbazia di Santa Maria della Grotta | J2: RUIN | K2: Campania
A3: Admont | B3: Benediktiner (1245-1571) | D3: AT-HHStA/dd618ca73597bb623bd4d1955b545862 | E3: =VLOOKUP(D3,fonds!$A$1:$B$495,2,FALSE()) -> AT-HHStA/AdmontOSB | F3: 2782979 | G3: 4757537 | H3: 1446075 | I3: Admont | J3: PPLA3 | K3: Styria
A4: Schlägl | B4: Prämonstratenser (1204-1600) | D4: AT-StiASchl/b3ad697a1c5c0f1d90adbf6cdae1835d | E4: =VLOOKUP(D4,fonds!$A$1:$B$495,2,FALSE()) -> AT-StiASchl/Urkunden | F4: 2782860 | G4: 4864578 | H4: 1397109 | I4: Aigen im Mühlkreis | J4: PPLA3 | K4: Upper Austria
A5: Aldersbach | B5: Kloster | C5: (Zisterzienser 1139-1791) | D5: DE-BayHStA/b215bd6dc8e1f8b5ad1fd3698e4125ce | E5: =VLOOKUP(D5,fonds!$A$1:$B$495,2,FALSE()) -> DE-BayHStA/KUAldersbach | F5: 2958577 | G5: 4858972 | H5: 1308971 | I5: Aldersbach | J5: PPLA4 | K5: Bavaria
A6: Zwettl | B6: Zisterzienser | D6: AT-HHStA/8c1d3d55acab28f955a37ccc994f297b | E6: =VLOOKUP(D6,fonds!$A$1:$B$495,2,FALSE()) -> AT-HHStA/ZwettlOCist | F6: 2782800 | G6: 4869725 | H6: 1532756 | I6: Allentsteig | J6: PPLA3 | K6: Lower Austria
A7: Allerheiligen | B7: Prämonstratenserkloster | D7: DE-GLAK/d2c4d62c3644cac106115b0f5877d032 | E7: =VLOOKUP(D7,fonds!$A$1:$B$495,2,FALSE()) -> DE-GLAK/GLAK_34 | F7: 2782797 | G7: 4691417 | H7: 1555444 | I7: Allerheiligen bei Wildon | J7: PPLA3 | K7: Styria
A8: Altenburg | B8: Benediktiner (1144-1943) | D8: AT-HHStA/0bc40b0184ca385dcc9f0a320889a6d2 | E8: =VLOOKUP(D8,fonds!$A$1:$B$495,2,FALSE()) -> AT-HHStA/AltenburgOSB | G8: 4864361 | H8: 1559465 | I8: Altenburg | K8: Lower Austria | L8: x
A9: Altenhohenau | B9: Kloster | C9: (Dominikanerinnen 1214-1800) | D9: DE-BayHStA/78d556f46555908f6dc08981ebfbb85c | E9: =VLOOKUP(D9,fonds!$A$1:$B$495,2,FALSE()) -> DE-BayHStA/KUAltenhohenau | F9: 2957590 | G9: 480204 | H9: 1218884 | I9: Altenhohenau | J9: FRST | K9: Bavaria
A10: Altomuenster | B10: Kloster | C10: (Benediktinerinnen 1256-1760) | D10: DE-BayHStA/b6e66024be4319ac4f2a52f17b798a5a | E10: =VLOOKUP(D10,fonds!$A$1:$B$495,2,FALSE()) -> DE-BayHStA/KUAltomuenster | F10: 2956951 | G10: 4838767 | H10: 1125691 | I10: Altomünster | J10: PPL | K10: Bavaria
A11: Alzey | B11: Augustinerkloster | D11: DE-UAHD/a4ab3acb9b37c3bffea705d4dc352e99 | E11: =VLOOKUP(D11,fonds!$A$1:$B$495,2,FALSE()) -> DE-UAHD/AlzeyAugustinerkloster | F11: 2956710 | G11: 4974657 | H11: 811513 | I11: Alzey | J11: PPLA3 | K11: Rheinland-Pfalz
A12: Amberg | B12: Salesianerinnen | D12: DE-StAAm/1026869f0920f53b66c69e0782fd6545 | E12: =VLOOKUP(D12,fonds!$A$1:$B$495,2,FALSE()) -> #N/A | F12: 2956656 | G12: 4944287 | H12: 1186267 | I12: Amberg | J12: PPLA3 | K12: Bavaria
A13: Arcetri | B13: S. Matteo a Lepore (agostiniane poi francescane) | D13: IT-ASFi/8c2e3ff7f9e0ad31feddc2e078866e00 | E13: =VLOOKUP(D13,fonds!$A$1:$B$495,2,FALSE()) -> IT-ASFi/DNArcetri | F13: 3182917 | G13: 43.75 | H13: 1123333 | I13: Arcetri | J13: PPL | K13: Tuscany
A14: Arezzo | B14: S. Bernardo (olivetani) | D14: IT-ASFi/9f2d29a9babc1a1f9adc98a9fb93a422 | E14: =VLOOKUP(D14,fonds!$A$1:$B$495,2,FALSE()) -> IT-ASFi/DNArezzoOlivetani | F14: 3182884 | G14: 4346276 | H14: 1188068 | I14: Arezzo | J14: PPLA2 | K14: Tuscany
A15: Arezzo | B15: S. Domenico (domenicani) | D15: IT-ASFi/e07b13e5a2e9431913a9a8671d03ba01 | E15: =VLOOKUP(D15,fonds!$A$1:$B$495,2,FALSE()) -> IT-ASFi/DNArezzoDomenicani | F15: 3182884 | G15: 4346276 | H15: 1188068 | I15: Arezzo | J15: PPLA2 | K15: Tuscany
A16: Arezzo | B16: S. Maria Novella (agostiniane) | D16: IT-ASFi/f28df954ff455f43dd23ed27cd27c755 | E16: =VLOOKUP(D16,fonds!$A$1:$B$495,2,FALSE()) -> IT-ASFi/DNArezzoSMariaNovella | F16: 3182884 | G16: 4346276 | H16: 1188068 | I16: Arezzo | J16: PPLA2 | K16: Tuscany
A17: Santa Maria de Armenteira | B17: Monasterio | D17: ES-AHN/036dff4ca827d80866e895f150b04d92 | E17: =VLOOKUP(D17,fonds!$A$1:$B$495,2,FALSE()) -> ES-AHN/SantaMariadeArmenteira | F17: 3129506 | G17: 4246667 | H17: -873333 | I17: Armenteira | J17: PPL | K17: Galicia
A18: Asbach | B18: Kloster | C18: (1270-1795) | D18: DE-BayHStA/cff195adfb040d2178e2567c8d5e0bde | E18: =VLOOKUP(D18,fonds!$A$1:$B$495,2,FALSE()) -> DE-BayHStA/KUAsbach | F18: 3208324 | G18: 4868333 | H18: 1081667 | I18: Asbach-Bäumenheim | J18: PPLA4 | K18: Bavaria
A19: Asparn | C19: (1471-1767) | D19: AT-AWMK/efcd58a04c971d71ae20524c11cefe16 | E19: =VLOOKUP(D19,fonds!$A$1:$B$495,2,FALSE()) -> AT-AWMK/AsparnOFMConv | F19: 2782319 | G19: 4858333 | H19: 46158 | I19: Asparn an der Zaya | J19: PPLA3 | K19: Lower Austria
A20: Coltibuono | B20: S. Lorenzo (badia | D20: IT-ASFi/96c23b03b25d558d5051efa6d9b560b9 | E20: =VLOOKUP(D20,fonds!$A$1:$B$495,2,FALSE()) -> IT-ASFi/DNColtibuonoSLorenzo | F20: 8980619 | G20: 4349476 | H20: 1144979 | I20: Badia Coltibuono | J20: PPL | K20: Tuscany
A21: Ripoli | B21: S. Bartolomeo (badia vallombrosana) | D21: IT-ASFi/6d1981b0b1bdaad659c9a51cd3d2b5de | E21: =VLOOKUP(D21,fonds!$A$1:$B$495,2,FALSE()) -> IT-ASFi/DNRipoliSBartolomeo | F21: 3182522 | G21: 4375115 | H21: 1132252 | I21: Bagno a Ripoli | J21: PPLA3 | K21: Tuscany
A22: Bakonybél | B22: Bences (PannH) (1246-1525) | D22: HU-PBFL/415c477be2e4b307e2f9487aa401db7d | E22: =VLOOKUP(D22,fonds!$A$1:$B$495,2,FALSE()) -> HU-PBFL/BakonybelOSB | F22: 3055646 | G22: 4725543 | H22: 1772805 | I22: Bakonybél | J22: PPL | K22: Veszprém
A23: Waldsassen | B23: Kloster | C23: (1132-1798) | D23: DE-StAAm/4450ccdc3028d1a033188de80e31112b | E23: =VLOOKUP(D23,fonds!$A$1:$B$495,2,FALSE()) -> DE-StAAm/Waldsassen | F23: 11608879 | G23: 5015776 | H23: 1163603 | I23: Basilika Waldsassen | J23: MSTY | K23: Bavaria
A24: Bebenhausen | B24: St. Blasien | D24: AT-StiAStP/eb2f9c1e052fd226a2ad578388d21ed2 | E24: =VLOOKUP(D24,fonds!$A$1:$B$495,2,FALSE()) -> AT-StiAStP/BlUKBebenhausen | F24: 11002373 | G24: 4856157 | H24: 906028 | I24: Bebenhausen Abbey | J24: MSTY | K24: Baden-Wurttemberg
A25: Berchtesgaden | B25: Augustiner-Chorherren (1202-1460) | D25: AT-HHStA/4ddf289639f88b3f075b379933eeb9d7 | E25: =VLOOKUP(D25,fonds!$A$1:$B$495,2,FALSE()) -> AT-HHStA/BerchtesgadenCanReg | F25: 2950881 | G25: 4763236 | H25: 1300187 | I25: Berchtesgaden | J25: PPL | K25: Bavaria
A26: Blaubeuren | B26: St. Blasien | D26: AT-StiAStP/82fe5329e02077bca9d11b7364258d75 | E26: =VLOOKUP(D26,fonds!$A$1:$B$495,2,FALSE()) -> AT-StiAStP/BlUKBlaubeuren | F26: 2947949 | G26: 4841215 | H26: 978427 | I26: Blaubeuren Abbey | J26: PPL | K26: Baden-Wurttemberg
A27: Bleidenstadt | B27: Stift St. Ferrutius (975-1790) | D27: DE-StAW/efdff395eff47b3116759f37f6bcf57c | E27: =VLOOKUP(D27,fonds!$A$1:$B$495,2,FALSE()) -> DE-StAW/BleidenstadtCan | F27: 2947822 | G27: 5013528 | H27: 814097 | I27: Bleidenstadt | J27: PPL | K27: Hesse
A28: Bludenz | B28: St. Peter | D28: AT-VLA/1130a191a42e1280b6862519c2526605 | E28: =VLOOKUP(D28,fonds!$A$1:$B$495,2,FALSE()) -> AT-VLA/BludenzStPeterKl | F28: 2781680 | G28: 4715476 | H28: 982255 | I28: Bludenz | J28: PPLA2 | K28: Vorarlberg
A29: Boskovice | B29: Dominikáni | C29: -1684 | D29: CZ-MZA/189ace968c03e66f96ac220fbd4a9b59 | E29: =VLOOKUP(D29,fonds!$A$1:$B$495,2,FALSE()) -> CZ-MZA/E11 | F29: 3078910 | G29: 4948751 | H29: 1665997 | I29: Boskovice | J29: PPL | K29: South Moravian
A30: Bregenz | B30: St. Annakloster | D30: AT-VLA/e6615ce73b7ea3c7ebd5d7fbe83253f1 | E30: =VLOOKUP(D30,fonds!$A$1:$B$495,2,FALSE()) -> AT-VLA/BregenzAnnakl | F30: 2781503 | G30: 4750311 | H30: 2035011 | I30: Bregenz | J30: PPLA | K30: Vorarlberg
C31: (1144-1943) | D31: AT-StiAA/7bcfdc2159154a251e578cc62430665d | E31: =VLOOKUP(D31,fonds!$A$1:$B$495,2,FALSE()) -> AT-StiAA/Urkunden | F31: 3078610 | G31: 4919522 | H31: 1660796 | I31: Brno | J31: PPLA | K31: South Moravian
D32: AT-StiAAdm/fd14928e00fdf9fe95f7e346bdacab4c | E32: =VLOOKUP(D32,fonds!$A$1:$B$495,2,FALSE()) -> AT-StiAAdm/Urkunden | F32: 3078610 | G32: 4919522 | H32: 1660796 | I32: Brno | J32: PPLA | K32: South Moravian
D33: AT-StiAFiecht/928a7927ff2674866fada1aa03283e9c | E33: =VLOOKUP(D33,fonds!$A$1:$B$495,2,FALSE()) -> AT-StiAFiecht/Urkunden | F33: 3078610 | G33: 4919522 | H33: 1660796 | I33: Brno | J33: PPLA | K33: South Moravian
C34: (1058-1899) | D34: AT-StiAG/665f9c7bfad49b61525dcd87314c9d19 | E34: =VLOOKUP(D34,fonds!$A$1:$B$495,2,FALSE()) -> AT-StiAG/GoettweigOSB | F34: 3078610 | G34: 4919522 | H34: 1660796 | I34: Brno | J34: PPLA | K34: South Moravian
C35: (1188-1992) | D35: AT-StiAGe/2a15f4c33d78f76165ac4af7531964bd | E35: =VLOOKUP(D35,fonds!$A$1:$B$495,2,FALSE()) -> AT-StiAGe/Urkunden | F35: 3078610 | G35: 4919522 | H35: 1660796 | I35: Brno | J35: PPLA | K35: South Moravian
C36: (777-1894) | D36: AT-StiAKr/63d0bd1c0c530a1a8ac2b2129d143380 | E36: =VLOOKUP(D36,fonds!$A$1:$B$495,2,FALSE()) -> AT-StiAKr/KremsmuensterOSB | F36: 3078610 | G36: 4919522 | H36: 1660796 | I36: Brno | J36: PPLA | K36: South Moravian
C37: (992-1600) | D37: AT-StiAL/c3e0dcc065fa079d1fe0a5a176b1d2a8 | E37: =VLOOKUP(D37,fonds!$A$1:$B$495,2,FALSE()) -> AT-StiAL/LambachOSB | F37: 3078610 | G37: 4919522 | H37: 1660796 | I37: Brno | J37: PPLA | K37: South Moravian
C38: (1075-1912) | D38: AT-StiAM/3181382eef393bdfe5100f9819e8e34b | E38: =VLOOKUP(D38,fonds!$A$1:$B$495,2,FALSE()) -> AT-StiAM/MelkOSB | F38: 3078610 | G38: 4919522 | H38: 1660796 | I38: Brno | J38: PPLA | K38: South Moravian
C39: (860-1400) | D39: AT-StiAMt/6445d4c11f9bdb02831b856ef3ecf7ca | E39: =VLOOKUP(D39,fonds!$A$1:$B$495,2,FALSE()) -> AT-StiAMt/MattseeCan | F39: 3078610 | G39: 4919522 | H39: 1660796 | I39: Brno | J39: PPLA | K39: South Moravian
C40: (1267-1881) | D40: AT-StiANK/22dd3dc1bee5255f0664b2f2ebaebde7 | E40: =VLOOKUP(D40,fonds!$A$1:$B$495,2,FALSE()) -> AT-StiANK/NeuklosterOCist | F40: 3078610 | G40: 4919522 | H40: 1660796 | I40: Brno | J40: PPLA | K40: South Moravian
...

Sheet Map-ToDo

Sheet CountByDecade
A1: fondsid | B1: Count bis 1500 | C1: 0 | D1: 16 | E1: 18 | F1: 47 | G1: 50 | H1: 64 | I1: 75 | J1: 76 | K1: 77 | L1: 78 | M1: 79 | N1: 80 | O1: 81 | P1: 82 | Q1: 83 | R1: 84 | S1: 85 | T1: 86 | U1: 87 | V1: 88 | W1: 89 | X1: 90 | Y1: 91 | Z1: 92 | AA1: 93 | AB1: 94 | AC1: 95 | AD1: 96 | AE1: 97 | AF1: 98 | AG1: 99 | AH1: 100 | AI1: 101 | AJ1: 102 | AK1: 103 | AL1: 104 | AM1: 105 | AN1: 106 | AO1: 107 | AP1: 108 | AQ1: 109 | AR1: 110 | AS1: 111 | AT1: 112 | AU1: 113 | AV1: 114 | AW1: 115 | AX1: 116 | AY1: 117 | AZ1: 118 | BA1: 119 | BB1: 120 | BC1: 121 | BD1: 122 | BE1: 123 | BF1: 124 | BG1: 125 | BH1: 126 | BI1: 127 | BJ1: 128 | BK1: 129 | BL1: 130 | BM1: 131 | BN1: 132 | BO1: 133 | BP1: 134 | BQ1: 135 | BR1: 136 | BS1: 137 | BT1: 138 | BU1: 139 | BV1: 140 | BW1: 141 | BX1: 142 | BY1: 143 | BZ1: 144 | CA1: 145 | CB1: 146 | CC1: 147 | CD1: 148 | CE1: 149 | CF1: 150 | CG1: 151 | CH1: 152 | CI1: 153 | CJ1: 154 | CK1: 155 | CL1: 156 | CM1: 157 | CN1: 158 | CO1: 159 | CP1: 160 | CQ1: 161 | CR1: 162 | CS1: 163 | CT1: 164 | CU1: 165 | CV1: 166 | CW1: 167 | CX1: 168 | CY1: 169 | CZ1: 170 | DA1: 171 | DB1: 172 | DC1: 173 | DD1: 174 | DE1: 175 | DF1: 176 | DG1: 177 | DH1: 178 | DI1: 179 | DJ1: 180 | DK1: 181 | DL1: 182 | DM1: 183 | DN1: 184 | DO1: 185 | DP1: 186 | DQ1: 187 | DR1: 188 | DS1: 189 | DT1: 190 | DU1: 191 | DV1: 192 | DW1: 193 | DX1: 194 | DY1: 195 | DZ1: 196 | EA1: 197 | EB1: 198 | EC1: 199 | ED1: 200 | EE1: 201 | EF1: 241 | EG1: 1000
A2: AT-ATF/TirolOFM | B2: =SUM(C2:CF2) -> 108 | BE2: 1 | BF2: 4 | BG2: 7 | BH2: 7 | BI2: 3 | BJ2: 3 | BK2: 3 | BL2: 3 | BM2: 2 | BN2: 5 | BP2: 1 | BQ2: 1 | BR2: 3 | BS2: 2 | BT2: 5 | BU2: 3 | BV2: 2 | BW2: 6 | BX2: 1 | BY2: 1 | BZ2: 6 | CA2: 6 | CB2: 6 | CC2: 10 | CD2: 7 | CE2: 3 | CF2: 7 | CG2: 12 | CH2: 14 | CI2: 6 | CJ2: 4 | CL2: 1 | CM2: 3 | CN2: 12 | CO2: 2 | CP2: 2 | CQ2: 9 | CR2: 13 | CS2: 25 | CT2: 25 | CU2: 8 | CV2: 5 | CW2: 5 | CX2: 7 | CY2: 23 | CZ2: 39 | DA2: 16 | DB2: 16 | DC2: 24 | DD2: 20 | DE2: 14 | DF2: 6 | DG2: 6 | DH2: 1 | DI2: 3 | DJ2: 5 | DK2: 2 | DL2: 4 | DM2: 2 | DN2: 2 | DQ2: 1 | DR2: 1 | DT2: 5 | DX2: 1 | DY2: 1 | DZ2: 1 | EA2: 1 | EG2: 6
A3: AT-AWMK/WienOFMConv | B3: =SUM(C3:CF3) -> 70 | BF3: 2 | BG3: 5 | BH3: 15 | BI3: 1 | BJ3: 17 | BK3: 1 | BL3: 2 | BN3: 3 | BO3: 3 | BP3: 3 | BQ3: 3 | BS3: 1 | BT3: 3 | BU3: 1 | BV3: 1 | BW3: 1 | BX3: 1 | BY3: 1 | BZ3: 1 | CA3: 2 | CD3: 1 | CF3: 2 | CG3: 3 | CH3: 4 | CI3: 2 | CJ3: 3 | CK3: 2 | CM3: 4 | CN3: 1 | CO3: 1 | CP3: 1 | CQ3: 6 | CR3: 4 | CS3: 1 | CT3: 5 | CU3: 6 | CV3: 3 | CW3: 8 | CY3: 3 | CZ3: 3 | DA3: 14 | DB3: 26 | DC3: 20 | DD3: 10 | DE3: 6 | DF3: 8 | DG3: 1
A4: AT-AWMK/NeunkirchenOFMConv | B4: =SUM(C4:CF4) -> 22 | BS4: 2 | BU4: 1 | BV4: 1 | BW4: 1 | BX4: 1 | BY4: 2 | BZ4: 1 | CA4: 3 | CB4: 2 | CD4: 2 | CE4: 1 | CF4: 5 | CG4: 3 | CH4: 9 | CK4: 2 | CM4: 2 | CN4: 1 | CO4: 1 | CP4: 1 | CR4: 1 | CS4: 2 | CY4: 1 | DA4: 1 | DC4: 7 | DF4: 1 | DI4: 1 | DM4: 1
A5: AT-AWMK/AsparnOFMConv | B5: =SUM(C5:CF5) -> 2 | CC5: 1 | CF5: 1 | CS5: 4 | CT5: 1 | CU5: 1 | CY5: 2 | CZ5: 2 | DA5: 3 | DB5: 7 | DC5: 7 | DD5: 4 | DE5: 6 | DF5: 8 | DG5: 1
A6: AT-HHStA/WienStLaurCanReg | B6: =SUM(C6:CF6) -> 62 | BN6: 1 | BR6: 1 | BS6: 5 | BU6: 1 | BW6: 8 | BX6: 1 | BY6: 2 | BZ6: 2 | CA6: 16 | CB6: 11 | CC6: 7 | CD6: 2 | CF6: 5 | CG6: 2 | CH6: 1 | CI6: 2 | CK6: 2 | CL6: 3 | CM6: 3 | CN6: 1 | CO6: 2 | CR6: 1 | CS6: 1 | CT6: 2 | CV6: 1 | CW6: 1 | CX6: 3 | CY6: 2 | CZ6: 3 | DB6: 1 | DD6: 4 | DE6: 3 | DF6: 2 | DG6: 3 | DH6: 1
A7: AT-HHStA/WiltenOPraem | B7: =SUM(C7:CF7) -> 3 | BA7: 1 | BG7: 1 | CE7: 1
A8: AT-HHStA/SeckauCanReg | B8: =SUM(C8:CF8) -> 57 | AY8: 4 | AZ8: 2 | BA8: 1 | BB8: 3 | BD8: 8 | BE8: 2 | BF8: 2 | BG8: 2 | BH8: 3 | BI8: 7 | BJ8: 6 | BK8: 6 | BL8: 7 | BU8: 1 | CC8: 1 | CD8: 1 | CE8: 1
A9: AT-HHStA/EbersbergOSB | B9: =SUM(C9:CF9) -> 8 | BG9: 2 | BK9: 2 | BL9: 2 | BU9: 1 | BX9: 1
A10: AT-HHStA/AltenburgOSB | B10: =SUM(C10:CF10) -> 4 | BJ10: 1 | BM10: 2 | BP10: 1
A11: AT-HHStA/StLambrechtOSB | B11: =SUM(C11:CF11) -> 14 | BC11: 1 | BD11: 2 | BL11: 1 | BU11: 1 | BX11: 1 | BY11: 4 | CB11: 1 | CF11: 3 | CK11: 1 | CM11: 1 | CN11: 1
A12: AT-HHStA/ArnsburgOCist | B12: =SUM(C12:CF12) -> 1 | CB12: 1
A13: AT-HHStA/WolfsbergOFMConv | B13: =SUM(C13:CF13) -> 5 | CB13: 2 | CD13: 1 | CF13: 2 | CG13: 1 | CH13: 2 | CK13: 1 | CP13: 1 | CQ13: 2 | CR13: 2
A14: AT-HHStA/MekinjeOSCI | B14: =SUM(C14:CF14) -> 1 | BQ14: 1 | CK14: 1
A15: AT-HHStA/ThalbachOFM | B15: =SUM(C15:CF15) -> 1 | CD15: 1 | CM15: 2 | CQ15: 4 | CR15: 5 | CU15: 1 | CW15: 1 | DD15: 3 | DG15: 2 | DH15: 1
A16: AT-HHStA/StBernhardOCist | B16: =SUM(C16:CF16) -> 195 | BH16: 3 | BI16: 9 | BJ16: 9 | BK16: 20 | BL16: 26 | BM16: 27 | BN16: 29 | BO16: 14 | BP16: 19 | BQ16: 22 | BR16: 7 | BT16: 1 | BV16: 1 | BW16: 1 | CA16: 1 | CB16: 3 | CD16: 1 | CE16: 2
A17: AT-HHStA/WienStNiklaskloster | B17: =SUM(C17:CF17) -> 1 | BY17: 1
A18: AT-HHStA/YbbsOCist | B18: =SUM(C18:CF18) -> 35 | BE18: 1 | BL18: 1 | BM18: 10 | BN18: 2 | BO18: 3 | BP18: 7 | BQ18: 1 | BR18: 2 | BT18: 1 | BV18: 4 | BW18: 2 | BX18: 1
A19: AT-HHStA/GrosswardeinOPraem | B19: =SUM(C19:CF19) -> 1 | BO19: 1
A20: AT-HHStA/NRannaOSPPE | B20: =SUM(C20:CF20) -> 3 | BZ20: 1 | CE20: 2 | CY20: 1
A21: AT-HHStA/GloggnitzOSB | B21: =SUM(C21:CF21) -> 1 | CD21: 1
A22: AT-HHStA/ImbachOP | B22: =SUM(C22:CF22) -> 9 | BI22: 1 | BK22: 2 | BL22: 1 | BP22: 1 | BT22: 1 | CB22: 2 | CF22: 1 | CM22: 1
A23: AT-HHStA/WNStPeterSpOP | B23: =SUM(C23:CF23) -> 8 | BQ23: 1 | BR23: 2 | BU23: 2 | BW23: 1 | BY23: 1 | CB23: 1 | CL23: 1 | CM23: 2
A24: AT-HHStA/StrebnitzOSB | B24: =SUM(C24:CF24) -> 1 | CC24: 1
A25: AT-HHStA/RadljeOP | B25: =SUM(C25:CF25) -> 29 | BI25: 7 | BJ25: 10 | BK25: 9 | BL25: 2 | CB25: 1
A26: AT-HHStA/SchnalsOCart | B26: =SUM(C26:CF26) -> 1 | BY26: 1
A27: AT-HHStA/KleinmariazellOSB | B27: =SUM(C27:CF27) -> 1 | CC27: 1
A28: AT-HHStA/PrahaMgd | B28: =SUM(C28:CF28) -> 1 | BV28: 1
A29: AT-HHStA/GamingOCart | B29: =SUM(C29:CF29) -> 1 | BR29: 1 | EG29: 103
A30: AT-HHStA/KlingenthalOP | B30: =SUM(C30:CF30) -> 2 | CD30: 2
A31: AT-HHStA/ErlaOSB | B31: =SUM(C31:CF31) -> 17 | BF31: 1 | BM31: 1 | BV31: 1 | BW31: 2 | BX31: 2 | BY31: 1 | CB31: 1 | CC31: 1 | CD31: 2 | CE31: 3 | CF31: 2 | CG31: 1 | CH31: 1 | CK31: 1 | CN31: 3 | CO31: 9 | CQ31: 2 | CR31: 1 | CZ31: 1
A32: AT-HHStA/StudeniceOP | B32: =SUM(C32:CF32) -> 27 | BG32: 3 | BH32: 4 | BI32: 5 | BJ32: 8 | BK32: 2 | BL32: 5
A33: AT-HHStA/PolaStMichaelDeMonta | B33: =SUM(C33:CF33) -> 1 | BW33: 1
A34: AT-HHStA/StainachOP | B34: =SUM(C34:CF34) -> 5 | CE34: 2 | CF34: 3
A35: AT-HHStA/BerchtesgadenCanReg | B35: =SUM(C35:CF35) -> 6 | BB35: 1 | BC35: 3 | BQ35: 1 | CB35: 1
A36: AT-HHStA/JudenburgOSCI | B36: =SUM(C36:CF36) -> 4 | BV36: 2 | CB36: 2
A37: AT-HHStA/PletrjeOCart | B37: =SUM(C37:CF37) -> 3 | CA37: 1 | CB37: 1 | CC37: 1
A38: AT-HHStA/SonnenburgOSB | B38: =SUM(C38:CF38) -> 2 | BP38: 1 | BU38: 1
A39: AT-HHStA/WienStClaraOSCI | B39: =SUM(C39:CF39) -> 260 | BL39: 2 | BM39: 14 | BN39: 17 | BO39: 13 | BP39: 27 | BQ39: 21 | BR39: 23 | BS39: 22 | BT39: 11 | BU39: 6 | BV39: 12 | BW39: 21 | BX39: 18 | BY39: 12 | BZ39: 9 | CA39: 4 | CB39: 6 | CC39: 9 | CD39: 3 | CE39: 8 | CF39: 2 | CG39: 2 | CI39: 3 | CJ39: 1 | CM39: 1
A40: AT-HHStA/KorneuburgOESA | B40: =SUM(C40:CF40) -> 10 | BM40: 1 | BP40: 2 | BR40: 1 | BS40: 1 | BT40: 1 | BU40: 1 | BW40: 1 | CB40: 1 | CF40: 1 | CG40: 1 | CH40: 1 | CJ40: 3 | CR40: 2 | CS40: 1 | CT40: 2 | CU40: 1 | CV40: 2 | DE40: 3 | DG40: 1
...

Sheet Dekaden
A1: Jahrzehnt | B1: 0 | C1: 16 | D1: 18 | E1: 47 | F1: 50 | G1: 64 | H1: 75 | I1: 76 | J1: 77 | K1: 78 | L1: 79 | M1: 80 | N1: 81 | O1: 82 | P1: 83 | Q1: 84 | R1: 85 | S1: 86 | T1: 87 | U1: 88 | V1: 89 | W1: 90 | X1: 91 | Y1: 92 | Z1: 93 | AA1: 94 | AB1: 95 | AC1: 96 | AD1: 97 | AE1: 98 | AF1: 99 | AG1: 100 | AH1: 101 | AI1: 102 | AJ1: 103 | AK1: 104 | AL1: 105 | AM1: 106 | AN1: 107 | AO1: 108 | AP1: 109 | AQ1: 110 | AR1: 111 | AS1: 112 | AT1: 113 | AU1: 114 | AV1: 115 | AW1: 116 | AX1: 117 | AY1: 118 | AZ1: 119 | BA1: 120 | BB1: 121 | BC1: 122 | BD1: 123 | BE1: 124 | BF1: 125 | BG1: 126 | BH1: 127 | BI1: 128 | BJ1: 129 | BK1: 130 | BL1: 131 | BM1: 132 | BN1: 133 | BO1: 134 | BP1: 135 | BQ1: 136 | BR1: 137 | BS1: 138 | BT1: 139 | BU1: 140 | BV1: 141 | BW1: 142 | BX1: 143 | BY1: 144 | BZ1: 145 | CA1: 146 | CB1: 147 | CC1: 148 | CD1: 149 | CE1: 150 | CF1: 151 | CG1: 152 | CH1: 153 | CI1: 154 | CJ1: 155 | CK1: 156 | CL1: 157 | CM1: 158 | CN1: 159 | CO1: 160 | CP1: 161 | CQ1: 162 | CR1: 163 | CS1: 164 | CT1: 165 | CU1: 166 | CV1: 167 | CW1: 168 | CX1: 169 | CY1: 170 | CZ1: 171 | DA1: 172 | DB1: 173 | DC1: 174 | DD1: 175 | DE1: 176 | DF1: 177 | DG1: 178 | DH1: 179 | DI1: 180 | DJ1: 181 | DK1: 182 | DL1: 183 | DM1: 184 | DN1: 185 | DO1: 186 | DP1: 187 | DQ1: 188 | DR1: 189 | DS1: 190 | DT1: 191 | DU1: 192 | DV1: 193 | DW1: 194 | DX1: 195 | DY1: 196 | DZ1: 197 | EA1: 198 | EB1: 199 | EC1: 200 | ED1: 201 | EE1: 241 | EF1: 1000
